[2024-05-17T09:15:31.189+0000] {task_context_logger.py:104} ERROR - Executor reports task instance <TaskInstance: example_decorator_dag.start_task scheduled__2024-05-16T00:00:00+00:00 [queued]> finished (failed) although the task says it's queued. (Info: None) Was the task killed externally?
