[2024-05-17T09:15:30.229+0000] {task_context_logger.py:104} ERROR - Executor reports task instance <TaskInstance: example_decorator_dag.start_task manual__2024-05-17T09:15:06.610000+00:00 [queued]> finished (failed) although the task says it's queued. (Info: None) Was the task killed externally?
